# PLANTA BAJA - connected rooms with real door openings and sight lines
# Main internal partitions: foyer, living room, kitchen, dining, office, cinema
fill ~35 ~3 ~35 ~60 ~8 ~35 minecraft:light_gray_concrete
fill ~35 ~3 ~36 ~35 ~8 ~51 minecraft:light_gray_concrete
fill ~60 ~3 ~35 ~60 ~8 ~51 minecraft:light_gray_concrete
fill ~60 ~3 ~43 ~84 ~8 ~43 minecraft:light_gray_concrete
fill ~72 ~3 ~43 ~72 ~8 ~52 minecraft:light_gray_concrete
fill ~36 ~3 ~33 ~52 ~8 ~33 minecraft:light_gray_concrete
fill ~52 ~3 ~33 ~52 ~8 ~43 minecraft:light_gray_concrete
# Wide openings between rooms (doors are added in the furniture phase)
fill ~46 ~3 ~35 ~50 ~6 ~35 minecraft:air
fill ~58 ~3 ~35 ~62 ~6 ~35 minecraft:air
fill ~60 ~3 ~40 ~60 ~6 ~42 minecraft:air
fill ~68 ~3 ~43 ~71 ~6 ~43 minecraft:air
fill ~72 ~3 ~47 ~72 ~6 ~49 minecraft:air
fill ~35 ~3 ~27 ~35 ~6 ~29 minecraft:air
fill ~85 ~3 ~31 ~85 ~6 ~33 minecraft:air
# Kitchen island and service wall
fill ~38 ~3 ~25 ~51 ~3 ~27 minecraft:polished_andesite
fill ~39 ~4 ~25 ~50 ~4 ~25 minecraft:quartz_slab[type=top]
fill ~38 ~3 ~29 ~51 ~4 ~29 minecraft:quartz_block
fill ~38 ~3 ~30 ~51 ~3 ~30 minecraft:quartz_slab[type=bottom]
# Cinema acoustic wall and stepped seating
fill ~63 ~3 ~45 ~83 ~8 ~45 minecraft:dark_oak_planks
fill ~63 ~3 ~46 ~83 ~3 ~50 minecraft:dark_oak_planks
fill ~65 ~4 ~47 ~81 ~4 ~47 minecraft:dark_oak_stairs[facing=south]
fill ~65 ~5 ~49 ~81 ~5 ~49 minecraft:dark_oak_stairs[facing=south]
# Office/library wall and ceiling beam
fill ~74 ~3 ~44 ~74 ~8 ~51 minecraft:dark_oak_planks
fill ~74 ~8 ~44 ~84 ~8 ~51 minecraft:dark_oak_planks
fill ~75 ~3 ~44 ~83 ~3 ~44 minecraft:bookshelf
fill ~75 ~4 ~44 ~83 ~4 ~44 minecraft:bookshelf
# Left wing: gym and guest lounge divider
fill ~21 ~3 ~24 ~21 ~8 ~52 minecraft:dark_oak_planks
fill ~21 ~3 ~38 ~30 ~8 ~38 minecraft:dark_oak_planks
fill ~22 ~3 ~38 ~26 ~6 ~38 minecraft:air
fill ~12 ~3 ~45 ~20 ~3 ~45 minecraft:polished_andesite
fill ~12 ~4 ~45 ~20 ~4 ~45 minecraft:quartz_slab[type=top]
# Right wing: bedrooms/service corridor
fill ~101 ~3 ~22 ~101 ~8 ~49 minecraft:polished_andesite
fill ~91 ~3 ~37 ~113 ~8 ~37 minecraft:light_gray_concrete
fill ~96 ~3 ~37 ~99 ~6 ~37 minecraft:air
fill ~105 ~3 ~37 ~108 ~6 ~37 minecraft:air
# Stair cores, each with a clear landing and headroom
fill ~76 ~3 ~24 ~84 ~3 ~31 minecraft:smooth_quartz
fill ~77 ~4 ~24 ~84 ~4 ~31 minecraft:air
fill ~77 ~4 ~25 ~77 ~4 ~30 minecraft:quartz_stairs[facing=south,half=bottom]
fill ~78 ~5 ~25 ~78 ~5 ~30 minecraft:quartz_stairs[facing=south,half=bottom]
fill ~79 ~6 ~25 ~79 ~6 ~30 minecraft:quartz_stairs[facing=south,half=bottom]
fill ~80 ~7 ~25 ~80 ~7 ~30 minecraft:quartz_stairs[facing=south,half=bottom]
fill ~81 ~8 ~25 ~81 ~8 ~30 minecraft:quartz_stairs[facing=south,half=bottom]
# Ground floor ceiling accents
fill ~38 ~9 ~24 ~51 ~9 ~24 minecraft:dark_oak_planks
fill ~38 ~9 ~29 ~51 ~9 ~29 minecraft:dark_oak_planks
fill ~64 ~9 ~23 ~82 ~9 ~23 minecraft:dark_oak_planks
fill ~64 ~9 ~50 ~82 ~9 ~50 minecraft:dark_oak_planks
