# MOBILIARIO PRIMERA PLANTA Y AZOTEA
# Master suite: oversized bed, headboard, side tables and seating
fill ~50 ~12 ~24 ~58 ~12 ~25 minecraft:dark_oak_planks
setblock ~52 ~13 ~24 minecraft:white_bed[facing=south,part=foot]
setblock ~52 ~13 ~25 minecraft:white_bed[facing=south,part=head]
setblock ~53 ~13 ~24 minecraft:white_bed[facing=south,part=foot]
setblock ~53 ~13 ~25 minecraft:white_bed[facing=south,part=head]
setblock ~51 ~13 ~27 minecraft:oak_slab[type=top]
setblock ~56 ~13 ~27 minecraft:oak_slab[type=top]
setblock ~49 ~13 ~28 minecraft:lantern[hanging=false]
setblock ~58 ~13 ~28 minecraft:lantern[hanging=false]
setblock ~50 ~13 ~31 minecraft:oak_stairs[facing=east]
setblock ~51 ~13 ~31 minecraft:oak_stairs[facing=west]
setblock ~57 ~13 ~31 minecraft:oak_stairs[facing=east]
setblock ~58 ~13 ~31 minecraft:oak_stairs[facing=west]
setblock ~51 ~13 ~40 minecraft:barrel[facing=up]
setblock ~53 ~13 ~40 minecraft:barrel[facing=up]
setblock ~55 ~13 ~40 minecraft:lectern[facing=east]
setblock ~57 ~13 ~41 minecraft:potted_azalea
# Master bath: double vanity, mirrors, shower and bathtub
fill ~49 ~12 ~30 ~54 ~12 ~30 minecraft:quartz_block
setblock ~49 ~13 ~30 minecraft:quartz_stairs[facing=east]
setblock ~51 ~13 ~30 minecraft:quartz_stairs[facing=east]
setblock ~53 ~13 ~30 minecraft:quartz_stairs[facing=west]
setblock ~49 ~14 ~30 minecraft:glass_pane
setblock ~51 ~14 ~30 minecraft:glass_pane
setblock ~53 ~14 ~30 minecraft:glass_pane
fill ~49 ~13 ~32 ~54 ~13 ~32 minecraft:quartz_block
fill ~49 ~14 ~32 ~54 ~14 ~32 minecraft:water
fill ~49 ~13 ~32 ~54 ~13 ~32 minecraft:quartz_block
fill ~49 ~14 ~31 ~54 ~14 ~31 minecraft:quartz_block
fill ~49 ~14 ~33 ~54 ~14 ~33 minecraft:quartz_block
setblock ~49 ~14 ~32 minecraft:quartz_block
setblock ~54 ~14 ~32 minecraft:quartz_block
fill ~50 ~14 ~32 ~53 ~14 ~32 minecraft:water
setblock ~57 ~13 ~31 minecraft:cauldron
setblock ~58 ~13 ~31 minecraft:iron_trapdoor[facing=north,half=top]
setblock ~57 ~13 ~32 minecraft:quartz_stairs[facing=west]
setblock ~58 ~13 ~32 minecraft:quartz_stairs[facing=west]
# Four guest bedrooms, each distinct but fully furnished
setblock ~68 ~13 ~24 minecraft:blue_bed[facing=east,part=foot]
setblock ~69 ~13 ~24 minecraft:blue_bed[facing=east,part=head]
setblock ~72 ~13 ~24 minecraft:oak_slab[type=top]
setblock ~74 ~13 ~24 minecraft:barrel[facing=up]
setblock ~68 ~13 ~31 minecraft:lantern[hanging=false]
setblock ~72 ~13 ~31 minecraft:bookshelf
setblock ~74 ~13 ~31 minecraft:lectern[facing=west]
setblock ~50 ~13 ~40 minecraft:green_bed[facing=east,part=foot]
setblock ~51 ~13 ~40 minecraft:green_bed[facing=east,part=head]
setblock ~54 ~13 ~40 minecraft:oak_slab[type=top]
setblock ~68 ~13 ~40 minecraft:yellow_bed[facing=east,part=foot]
setblock ~69 ~13 ~40 minecraft:yellow_bed[facing=east,part=head]
setblock ~72 ~13 ~40 minecraft:oak_slab[type=top]
setblock ~75 ~13 ~40 minecraft:potted_blue_orchid
# Secondary bathrooms and corridor lounge
setblock ~64 ~13 ~31 minecraft:quartz_stairs[facing=east]
setblock ~66 ~13 ~31 minecraft:quartz_stairs[facing=west]
setblock ~64 ~14 ~31 minecraft:glass_pane
setblock ~66 ~14 ~31 minecraft:glass_pane
setblock ~74 ~13 ~36 minecraft:gray_carpet
setblock ~75 ~13 ~36 minecraft:gray_carpet
setblock ~76 ~13 ~36 minecraft:gray_carpet
setblock ~75 ~13 ~38 minecraft:oak_slab[type=top]
setblock ~76 ~13 ~38 minecraft:oak_slab[type=top]
setblock ~75 ~13 ~42 minecraft:lantern[hanging=false]
# Rooftop bar, lounge seating and planters
fill ~56 ~21 ~29 ~70 ~21 ~29 minecraft:dark_oak_planks
setblock ~58 ~22 ~29 minecraft:barrel[facing=up]
setblock ~60 ~22 ~29 minecraft:barrel[facing=up]
setblock ~62 ~22 ~29 minecraft:brewing_stand
setblock ~64 ~22 ~29 minecraft:cauldron
setblock ~66 ~22 ~29 minecraft:barrel[facing=up]
setblock ~58 ~21 ~34 minecraft:quartz_stairs[facing=east]
setblock ~59 ~21 ~34 minecraft:quartz_stairs[facing=west]
setblock ~68 ~21 ~34 minecraft:quartz_stairs[facing=east]
setblock ~69 ~21 ~34 minecraft:quartz_stairs[facing=west]
setblock ~60 ~21 ~36 minecraft:gray_carpet
setblock ~61 ~21 ~36 minecraft:gray_carpet
setblock ~67 ~21 ~36 minecraft:gray_carpet
setblock ~68 ~21 ~36 minecraft:gray_carpet
setblock ~56 ~21 ~30 minecraft:potted_azalea
setblock ~72 ~21 ~30 minecraft:potted_allium
setblock ~58 ~21 ~37 minecraft:lantern[hanging=false]
setblock ~70 ~21 ~37 minecraft:lantern[hanging=false]
