# GARAGE, DRIVE, GARDENS AND OUTDOOR LIVING
fill ~91 ~3 ~55 ~113 ~3 ~65 minecraft:polished_andesite
fill ~93 ~4 ~55 ~111 ~4 ~55 minecraft:sea_lantern
fill ~93 ~5 ~55 ~111 ~5 ~55 minecraft:gray_concrete
fill ~94 ~3 ~57 ~101 ~3 ~57 minecraft:quartz_slab[type=bottom]
fill ~104 ~3 ~57 ~111 ~3 ~57 minecraft:quartz_slab[type=bottom]
fill ~94 ~4 ~57 ~101 ~4 ~57 minecraft:sea_lantern
fill ~104 ~4 ~57 ~111 ~4 ~57 minecraft:sea_lantern
fill ~93 ~3 ~62 ~111 ~3 ~62 minecraft:polished_blackstone
fill ~93 ~4 ~62 ~93 ~7 ~62 minecraft:barrel
fill ~111 ~4 ~62 ~111 ~7 ~62 minecraft:barrel
setblock ~96 ~4 ~64 minecraft:crafting_table
setblock ~98 ~4 ~64 minecraft:smithing_table
setblock ~100 ~4 ~64 minecraft:anvil
setblock ~106 ~4 ~64 minecraft:chest[facing=north]
setblock ~108 ~4 ~64 minecraft:chest[facing=north]
setblock ~110 ~4 ~64 minecraft:lantern[hanging=false]
# Garden beds between wings
fill ~33 ~1 ~24 ~33 ~1 ~52 minecraft:quartz_block
fill ~34 ~1 ~24 ~34 ~1 ~52 minecraft:oak_leaves[persistent=true]
fill ~86 ~1 ~24 ~87 ~1 ~52 minecraft:oak_leaves[persistent=true]
fill ~30 ~1 ~57 ~39 ~1 ~68 minecraft:grass_block
fill ~31 ~1 ~58 ~38 ~1 ~67 minecraft:coarse_dirt
setblock ~32 ~2 ~59 minecraft:oak_log[axis=y]
fill ~30 ~3 ~57 ~34 ~5 ~61 minecraft:oak_leaves[persistent=true]
fill ~35 ~3 ~64 ~39 ~5 ~68 minecraft:oak_leaves[persistent=true]
setblock ~31 ~2 ~65 minecraft:potted_azalea
setblock ~38 ~2 ~60 minecraft:potted_allium
setblock ~31 ~1 ~57 minecraft:lantern[hanging=false]
setblock ~38 ~1 ~67 minecraft:lantern[hanging=false]
# Rear garden, lawn and hedge grid
fill ~82 ~1 ~56 ~88 ~1 ~69 minecraft:grass_block
fill ~84 ~2 ~58 ~84 ~4 ~58 minecraft:oak_leaves[persistent=true]
fill ~86 ~2 ~61 ~86 ~4 ~61 minecraft:oak_leaves[persistent=true]
fill ~84 ~2 ~64 ~84 ~4 ~64 minecraft:oak_leaves[persistent=true]
fill ~86 ~2 ~67 ~86 ~4 ~67 minecraft:oak_leaves[persistent=true]
fill ~82 ~1 ~55 ~88 ~1 ~55 minecraft:stone_brick_slab[type=bottom]
setblock ~85 ~1 ~57 minecraft:lantern[hanging=false]
setblock ~85 ~1 ~69 minecraft:lantern[hanging=false]
# Exterior dining / BBQ terrace
fill ~18 ~1 ~56 ~31 ~1 ~67 minecraft:dark_oak_planks
fill ~19 ~2 ~57 ~30 ~2 ~57 minecraft:dark_oak_fence
fill ~19 ~2 ~66 ~30 ~2 ~66 minecraft:dark_oak_fence
setblock ~22 ~2 ~61 minecraft:campfire[lit=true]
setblock ~22 ~3 ~61 minecraft:chain[axis=y]
setblock ~25 ~2 ~61 minecraft:smoker[facing=east]
setblock ~27 ~2 ~61 minecraft:barrel[facing=up]
setblock ~20 ~2 ~58 minecraft:lantern[hanging=false]
setblock ~29 ~2 ~58 minecraft:lantern[hanging=false]
setblock ~24 ~2 ~64 minecraft:quartz_stairs[facing=east]
setblock ~25 ~2 ~64 minecraft:quartz_stairs[facing=west]
