# ROOFTOP AND POOL - water is enclosed by a raised quartz rim on all sides
fill ~44 ~19 ~46 ~84 ~19 ~54 minecraft:dark_oak_planks
fill ~46 ~20 ~48 ~82 ~20 ~52 minecraft:quartz_slab[type=bottom]
fill ~56 ~19 ~26 ~74 ~19 ~40 minecraft:polished_andesite
fill ~58 ~20 ~28 ~72 ~20 ~38 minecraft:grass_block
fill ~58 ~21 ~28 ~72 ~22 ~38 minecraft:air
fill ~57 ~23 ~27 ~73 ~23 ~39 minecraft:dark_oak_planks
fill ~58 ~23 ~28 ~72 ~23 ~38 minecraft:air
fill ~42 ~2 ~56 ~80 ~2 ~68 minecraft:quartz_block
fill ~43 ~3 ~57 ~79 ~3 ~67 minecraft:quartz_slab[type=bottom]
fill ~44 ~2 ~58 ~78 ~3 ~66 minecraft:water
fill ~43 ~2 ~57 ~79 ~3 ~57 minecraft:quartz_block
fill ~43 ~2 ~67 ~79 ~3 ~67 minecraft:quartz_block
fill ~43 ~2 ~57 ~43 ~3 ~67 minecraft:quartz_block
fill ~79 ~2 ~57 ~79 ~3 ~67 minecraft:quartz_block
fill ~43 ~4 ~57 ~79 ~4 ~67 minecraft:air
fill ~42 ~4 ~56 ~80 ~4 ~56 minecraft:quartz_block
fill ~42 ~4 ~68 ~80 ~4 ~68 minecraft:quartz_block
fill ~42 ~4 ~56 ~42 ~4 ~68 minecraft:quartz_block
fill ~80 ~4 ~56 ~80 ~4 ~68 minecraft:quartz_block
fill ~45 ~4 ~58 ~77 ~4 ~58 minecraft:sea_lantern
fill ~45 ~4 ~66 ~77 ~4 ~66 minecraft:sea_lantern
fill ~44 ~2 ~60 ~44 ~3 ~64 minecraft:quartz_stairs[facing=east,half=bottom]
fill ~78 ~2 ~60 ~78 ~3 ~64 minecraft:quartz_stairs[facing=west,half=bottom]
# Shallow sun shelf and diving end, both bounded by the same rim
fill ~46 ~3 ~59 ~55 ~3 ~61 minecraft:water
fill ~46 ~3 ~62 ~55 ~3 ~64 minecraft:water
fill ~58 ~2 ~57 ~64 ~2 ~57 minecraft:quartz_slab[type=bottom]
fill ~66 ~2 ~57 ~72 ~2 ~57 minecraft:quartz_slab[type=bottom]
fill ~58 ~3 ~57 ~64 ~3 ~57 minecraft:sea_lantern
fill ~66 ~3 ~57 ~72 ~3 ~57 minecraft:sea_lantern
# Upper pergola and fire lounge
fill ~48 ~20 ~48 ~48 ~24 ~54 minecraft:dark_oak_log[axis=y]
fill ~80 ~20 ~48 ~80 ~24 ~54 minecraft:dark_oak_log[axis=y]
fill ~48 ~24 ~48 ~80 ~24 ~54 minecraft:dark_oak_slab[type=bottom]
fill ~54 ~20 ~49 ~74 ~20 ~53 minecraft:dark_oak_planks
setblock ~63 ~21 ~51 minecraft:campfire[lit=true]
setblock ~63 ~22 ~51 minecraft:chain[axis=y]
setblock ~51 ~21 ~50 minecraft:quartz_stairs[facing=east]
setblock ~52 ~21 ~50 minecraft:quartz_stairs[facing=west]
setblock ~74 ~21 ~50 minecraft:quartz_stairs[facing=east]
setblock ~75 ~21 ~50 minecraft:quartz_stairs[facing=west]
setblock ~55 ~21 ~53 minecraft:barrel[facing=up]
setblock ~72 ~21 ~53 minecraft:barrel[facing=up]
setblock ~50 ~21 ~52 minecraft:lantern[hanging=false]
setblock ~78 ~21 ~52 minecraft:lantern[hanging=false]
